<?xml version="1.0"?>
<!-- Revolute-Revolute Manipulator -->
<robot name="rrbot" xmlns:xacro="http://www.ros.org/wiki/xacro">

  <!-- Constants for robot dimensions -->
  <xacro:property name="PI" value="3.1415926535897931"/>
  <xacro:property name="mass" value="1" />

  <xacro:property name="pos_x" value="2" />
  <xacro:property name="pos_y" value="0" />
  <xacro:property name="pos_z" value="1" />
  <xacro:property name="obj_x" value="0.25" />
  <xacro:property name="obj_y" value="0.25" />
  <xacro:property name="obj_z" value="0.25" />

  <!-- Import all Gazebo-customization elements, including Gazebo colors -->
  <xacro:include filename="$(find rrbot_description)/urdf/rrbot.gazebo" />
  <!-- Import Rviz colors -->
  <xacro:include filename="$(find rrbot_description)/urdf/materials.xacro" />

  <!-- Used for fixing robot to Gazebo 'base_link' -->
  <link name="world"/>

  <joint name="fixed" type="fixed">
    <parent link="world"/>
    <child link="link1"/>
  </joint>

  <!-- Base Link -->
  <link name="link1">
    <inertial>
      <origin xyz="0 0 0.001" rpy="0 0 0"/>
      <mass value="${mass}"/>
      <inertia
      ixx="0.0" ixy="0.0" ixz="0.0"
	  iyy="0.0" iyz="0.0"
	  izz="0.0"/>
    </inertial>
  </link>

  <joint name="joint1" type="continuous">
    <parent link="link1"/>
    <child link="link2"/>
    <origin xyz="0 0 0" rpy="0 0 0"/>
    <axis xyz="0 1 0"/>
    <dynamics damping="0.3"/>
  </joint>

  <!-- Middle Link -->
  <link name="link2">
    <inertial>
      <origin xyz="0 0 0.01" rpy="0 0 0"/>
      <mass value="${mass}"/>
      <inertia
      ixx="0.0" ixy="0.0" ixz="0.0"
	  iyy="0.0" iyz="0.0"
	  izz="0.0"/>
    </inertial>
  </link>

  <joint name="joint2" type="continuous">
    <parent link="link2"/>
    <child link="link3"/>
    <origin xyz="0 0 0" rpy="0 0 0"/>
    <axis xyz="0 0 1"/>
    <dynamics damping="0.3"/>
  </joint>

  <!-- Middle Link -->
  <link name="link3">
    <inertial>
      <origin xyz="0 0 0.01" rpy="0 0 0"/>
      <mass value="${mass}"/>
      <inertia
      ixx="0.0" ixy="0.0" ixz="0.0"
	  iyy="0.0" iyz="0.0"
	  izz="0.0"/>
    </inertial>
  </link>

  <joint name="joint3" type="continuous">
    <parent link="link3"/>
    <child link="link4"/>
    <origin xyz="${pos_x} ${pos_y} ${pos_z}" rpy="0 0 0"/>
    <axis xyz="1 0 0"/>
    <dynamics damping="0.3"/>
  </joint>

  <!-- Top Link -->
  <link name="link4">
    <inertial>
      <origin xyz="0 0 0.1" rpy="0 0 0"/>
      <mass value="${mass}"/>
      <inertia
      ixx="0.0" ixy="0.0" ixz="0.0"
	  iyy="0.0" iyz="0.0"
	  izz="0.0"/>
    </inertial>
    <visual>
      <origin xyz="0 0 0" rpy="0 0 0"/>
      <geometry>
        <box size="${obj_x} ${obj_y} ${obj_z}"/>
      </geometry>
      <material name="gray"/>
    </visual>

  </link>

  <transmission name="tran1">
    <type>transmission_interface/SimpleTransmission</type>
    <joint name="joint1">
      <hardwareInterface>hardware_interface/VelocityJointInterface</hardwareInterface>
    </joint>
    <actuator name="motor1">
      <hardwareInterface>hardware_interface/VelocityJointInterface</hardwareInterface>
      <mechanicalReduction>1</mechanicalReduction>
    </actuator>
  </transmission>

  <transmission name="tran2">
    <type>transmission_interface/SimpleTransmission</type>
    <joint name="joint2">
      <hardwareInterface>hardware_interface/VelocityJointInterface</hardwareInterface>
    </joint>
    <actuator name="motor2">
      <hardwareInterface>hardware_interface/VelocityJointInterface</hardwareInterface>
      <mechanicalReduction>1</mechanicalReduction>
    </actuator>
  </transmission>

  <transmission name="tran3">
    <type>transmission_interface/SimpleTransmission</type>
    <joint name="joint3">
      <hardwareInterface>hardware_interface/VelocityJointInterface</hardwareInterface>
    </joint>
    <actuator name="motor3">
      <hardwareInterface>hardware_interface/VelocityJointInterface</hardwareInterface>
      <mechanicalReduction>1</mechanicalReduction>
    </actuator>
  </transmission>

</robot>
